Workbook

Sheet Cover
C2: TEST CASE
B4: Project Name | C4: S-HOME - Hệ thống quản trị | F4: Creator | G4: Dương Thị Ngọc Ánh
B5: Project Code | C5: SH01 | F5: Reviewer/Approver
B6: Document Code | F6: Issue Date | G6: 20/09/2026
F7: Version | G7: 1.0
B10: Change Date | C10: Change Item | D10: Change description | E10: ID Name | F10: Note
A41: TC31
A42: TC32
A43: TC33
A44: TC34
A45: TC35
A46: TC36
A47: TC37
A48: TC38
A49: TC39
A50: TC40
A51: TC41
A52: TC42
... A65: TC54

Sheet TestReport
B1: TEST REPORT
B3: Project Name | C3: S-HOME - Hệ thống quản trị | E3: Creator | G3: =Cover!$G$4 -> Dương Thị Ngọc Ánh
B4: Project Code | C4: SH01 | E4: Reviewer/Approver
B5: Document Code | E5: Issue Date | G5: 20/09/2026
B6: Notes
B10: NO | C10: Test Items | D10: Pass | E10: Fail | F10: NT | G10: N/A | H10: Number of test cases
B11: 1 | C11: ='Test QuanLyChiNhanh'!B2 -> Kiểm thử chức năng quản lý chi nhánh (Thêm/Sửa/Xóa) | D11: ='Test QuanLyChiNhanh'!A5 -> 44 | E11: ='Test QuanLyChiNhanh'!B5 -> 10 | F11: ='Test QuanLyChiNhanh'!C5 -> 0 | G11: ='Test QuanLyChiNhanh'!D5 -> 0 | H11: ='Test QuanLyChiNhanh'!E5 -> 54
B12: 2 | C12: ='Test QuanLyThuongHieu'!B2 -> Kiểm thử chức năng tạo thương hiệu | D12: ='Test QuanLyThuongHieu'!A5 -> 25 | E12: ='Test QuanLyThuongHieu'!B5 -> 9 | F12: ='Test QuanLyThuongHieu'!C5 -> 0 | G12: ='Test QuanLyThuongHieu'!D5 -> 0 | H12: ='Test QuanLyThuongHieu'!E5 -> 34
B13: 3 | C13: ='Test QuanLyKho'!B2 -> Kiểm thử chức năng tạo kho | D13: ='Test QuanLyKho'!A5 -> 44 | E13: ='Test QuanLyKho'!B5 -> 6 | F13: ='Test QuanLyKho'!C5 -> 1 | G13: ='Test QuanLyKho'!D5 -> 0 | H13: ='Test QuanLyKho'!E5 -> 51
C15: Sub total | D15: =SUM(D11:D13) -> 113 | E15: =SUM(E11:E13) -> 25 | F15: =SUM(F11:F13) -> 1 | G15: =SUM(G11:G13) -> 0 | H15: =SUM(H11:H13) -> 139
C17: Test coverage | E17: =IFERROR((D15+E15)*100/H15,0) -> 99.280576 | F17: %
C18: Test successful coverage | E18: =IFERROR(D15*100/(D15+E15),0) -> 81.884058 | F18: %
A42: TC31
A43: TC32
A44: TC33
A45: TC34
A46: TC35
A47: TC36
A48: TC37
A49: TC38
A50: TC39
A51: TC40
A52: TC41
A53: TC42
... A66: TC54

Sheet Test QuanLyChiNhanh
A1: Item Test | B1: QuanLyChiNhanh
A2: Test Requirement | B2: Kiểm thử chức năng quản lý chi nhánh (Thêm/Sửa/Xóa)
A3: Tester | B3: =Cover!$G$4 -> Dương Thị Ngọc Ánh
A4: Pass | B4: Fail | C4: NT | D4: N/A | E4: Number of Test cases
A5: =COUNTIF(G:G,"Pass") -> 44 | B5: =COUNTIF(G:G,"Fail") -> 10 | C5: =COUNTIF(G:G,"Untested") -> 0 | D5: =COUNTIF(G:G,"N/A") -> 0 | E5: =SUM(A5:D5) -> 54
A6: % | B6: % | C6: % | D6: %
A7: =IFERROR(A5/$E$5,0) -> 0.81481481 | B7: =IFERROR(B5/$E$5,0) -> 0.18518519 | C7: =IFERROR(C5/$E$5,0) -> 0 | D7: =IFERROR(D5/$E$5,0) -> 0 | E7: =IFERROR(E5/$E$5,0) -> 1
A8: ID | B8: Test Case Description | C8: Pre-condition | D8: Test Case Procedure | E8: Test Data | F8: Expected Output | G8: Result | H8: Test date | I8: Tester | J8: Note
B10: 1. Thêm xhi nhánh
A11: TC01 | B11: Kiểm tra textbox "Mã chi nhánh" | D11: Vào màn hình, quan sát textbox | E11: … | F11: 1. Hiển thị textbox với border, padding, height đúng design 2. Hiển thị placeholder "Mã chi nhánh" 3. Border-radius, màu border đúng design | G11: Pass | I11: =Cover!$G$4 -> Dương Thị Ngọc Ánh
A12: TC02 | B12: Kiểm tra dòng ghi chú dưới "Mã chi nhánh" | D12: Vào màn hình, quan sát text dưới field | E12: … | F12: 1. Hiển thị chữ "Mã duy nhất, không thể thay đổi sau khi tạo" 2. Font-size, màu sắc (xám/nhạt) đúng design | G12: Pass | I12: =Cover!$G$4 -> Dương Thị Ngọc Ánh
A13: TC03 | B13: Kiểm tra label "Loại chi nhánh" | D13: Vào màn hình, quan sát label | E13: … | F13: 1. Label: Loại chi nhánh 2. Hiển thị dạng floating label nằm trên viền dropdown 3. Font-size, màu sắc đúng design | G13: Pass | I13: =Cover!$G$4 -> Dương Thị Ngọc Ánh
A14: TC04 | B14: Kiểm tra dropdown "Loại chi nhánh" | D14: Vào màn hình, quan sát dropdown | E14: … | F14: 1. Hiển thị dropdown với border, padding, height đúng design 2. Giá trị mặc định: "Chi nhánh" 3. Có icon mũi tên xổ xuống bên phải 4. Border-radius, màu border đúng design | G14: Pass | I14: =Cover!$G$4 -> Dương Thị Ngọc Ánh
A15: TC05 | B15: Kiểm tra click mở dropdown "Loại chi nhánh" | D15: Click vào dropdown "Loại chi nhánh" | E15: … | F15: 1. Hiển thị danh sách các loại chi nhánh xổ xuống đầy đủ | G15: Pass | I15: =Cover!$G$4 -> Dương Thị Ngọc Ánh
A16: TC06 | B16: Kiểm tra chọn giá trị khác trong dropdown "Loại chi nhánh" | D16: 1. Click dropdown 2. Chọn một giá trị khác mặc định | E16: … | F16: 1. Giá trị được chọn hiển thị đúng trong dropdown 2. Dropdown đóng lại | G16: Pass | I16: =Cover!$G$4 -> Dương Thị Ngọc Ánh
A17: TC07 | B17: Kiểm tra textbox "Địa chỉ" | D17: Vào màn hình, quan sát textbox | E17: … | F17: 1. Hiển thị textbox với border, padding, height đúng design 2. Hiển thị placeholder "Địa chỉ" 3. Chiều rộng full theo layout 4. Border-radius, màu border đúng design | G17: Pass | I17: =Cover!$G$4 -> Dương Thị Ngọc Ánh
A18: TC08 | B18: Kiểm tra textbox "Số điện thoại" | D18: Vào màn hình, quan sát textbox | E18: … | F18: 1. Hiển thị textbox với border, padding, height đúng design 2. Hiển thị placeholder "Số điện thoại" 3. Border-radius, màu border đúng design | G18: Pass | I18: =Cover!$G$4 -> Dương Thị Ngọc Ánh
A19: TC09 | B19: Kiểm tra textbox "Email" | D19: Vào màn hình, quan sát textbox | E19: … | F19: 1. Hiển thị textbox với border, padding, height đúng design 2. Hiển thị placeholder "Email" 3. Border-radius, màu border đúng design | G19: Pass | I19: =Cover!$G$4 -> Dương Thị Ngọc Ánh
A20: TC10 | B20: Kiểm tra toggle "Đang hoạt động" mặc định bật | D20: Vào màn hình, quan sát toggle | E20: … | F20: 1. Toggle hiển thị trạng thái bật (ON) mặc định, màu cam 2. Label "Đang hoạt động" hiển thị đúng font-size, màu sắc 3. Kích thước, border-radius toggle đúng design | G20: Pass | I20: =Cover!$G$4 -> Dương Thị Ngọc Ánh
A21: TC11 | B21: Kiểm tra click tắt/bật toggle "Đang hoạt động" | D21: 1. Click toggle để tắt 2. Click lại để bật | E21: … | F21: 1. Lần 1: toggle chuyển sang tắt (xám) 2. Lần 2: toggle chuyển lại bật (cam) | G21: Pass | I21: =Cover!$G$4 -> Dương Thị Ngọc Ánh
A22: TC12 | B22: Kiểm tra button "Hủy" | D22: Vào màn hình, quan sát button | E22: … | F22: 1. Hiển thị chữ "Hủy" 2. Màu nền trắng, viền xám, border-radius đúng design 3. Vị trí góc phải dưới cùng form | G22: Pass | I22: =Cover!$G$4 -> Dương Thị Ngọc Ánh
A23: TC13 | B23: Kiểm tra button "Tạo mới" | D23: Vào màn hình, quan sát button | E23: … | F23: 1. Hiển thị chữ "Tạo mới" kèm icon 2. Màu nền cam, chữ đen/đậm, border-radius đúng design 3. Vị trí góc phải dưới cùng, cạnh button "Hủy" | G23: Pass | I23: =Cover!$G$4 -> Dương Thị Ngọc Ánh
A24: TC14 | B24: Thêm chi nhánh với đầy đủ dữ liệu hợp lệ | C24: Đã mở form Thêm chi nhánh | D24: 1. Nhập Tên chi nhánh. 2. Nhập Mã chi nhánh. 3. Chọn Loại chi nhánh. 4. Nhập địa chỉ. 5. Nhập số điện thoại. 6. Nhập email. 7. Giữ toggle Đang hoạt động ở trạng thái ON. 8. Click Tạo mới. 9. Mở lại danh sách chi nhánh. | E24: Tên: Chi nhánh Bắc Ninh Mã: BN001 Loại: Chi nhánh Địa chỉ: 132 Nguyễn Cao, Kinh Bắc, Bắc Ninh SĐT: 0286437491 Email: bn001@shome.vn Trạng thái: ON | F24: 1. Chi nhánh được tạo thành công. 2. Hiển thị thông báo “Tạo chi nhánh thành công”. 3. Chi nhánh BN001 xuất hiện trong danh sách. 4. Các thông tin hiển thị đúng với dữ liệu đã nhập. 5. Trạng thái hiển thị là Ngừng hoạt động. 6. Reload trang vẫn còn chi nhánh vừa tạo. | G24: Fail | I24: =Cover!$G$4 -> Dương Thị Ngọc Ánh | J24: 1. Khi lưu danh sách chi nhánh hiển thị trạng thái không hoạt động 2. Chọn loại “Chi nhánh” khi tạo nhưng khi xem chi tiết lại hiển thị “Trụ sở chính”.
A25: TC15 | B25: Tạo chi nhánh chỉ với các trường bắt buộc | D25: 1. Click "Thêm chi nhánh". 2. Nhập Tên chi nhánh. 3. Nhập Mã chi nhánh. 4. Giữ nguyên các trường Địa chỉ, SĐT, Email ở trạng thái để trống. 5. Giữ toggle "Đang hoạt động" ở trạng thái mặc định. 6. Click "Tạo mới". 7. Kiểm tra thông báo và danh sách chi nhánh. | E25: Tên: Chi nhánh Test 02 Mã: C0021 Trạng thái: Đang hoạt động | F25: 1. Hệ thống không hiển thị lỗi validation đối với các trường Địa chỉ, SĐT, Email. 2. Chi nhánh được tạo thành công. 3. Hiển thị thông báo "Tạo chi nhánh thành công". 4. Chi nhánh mới xuất hiện trong danh sách với đúng Tên, Mã và trạng thái đã chọn. 5. Không phát sinh bản ghi trùng. | G25: Fail | I25: =Cover!$G$4 -> Dương Thị Ngọc Ánh | J25: Không tạo đc chi nhành mới
A26: TC16 | B26: Hủy tạo chi nhánh khi chưa nhập dữ liệu | D26: 1. Không nhập dữ liệu vào form. 2. Click "Hủy" | E26: … | F26: 1. Hệ thống quay về Danh sách chi nhánh. 2. Không tạo chi nhánh mới. 3. Không xuất hiện bản ghi mới trong danh sách. | G26: Pass | I26: =Cover!$G$4 -> Dương Thị Ngọc Ánh
A27: TC17 | B27: Hủy tạo chi nhánh sau khi đã nhập dữ liệu | D27: 1. Nhập Tên chi nhánh. 2. Nhập Mã chi nhánh. 3. Nhập một số thông tin khác. 4. Click Hủy. 5. Kiểm tra danh sách chi nhánh. | E27: Tên: Chi nhánh Test Hủy Mã: CN_CANCEL01 | F27: 1. Hệ thống quay về Danh sách chi nhánh. 2. Dữ liệu vừa nhập không được lưu. 3. Không tìm thấy mã CN_CANCEL01 trong danh sách. | G27: Pass | I27: =Cover!$G$4 -> Dương Thị Ngọc Ánh
A28: TC18 | B28: Bỏ trống Tên chi nhánh | D28: 1. Để trống Tên chi nhánh. 2. Nhập Mã chi nhánh. 3. Nhập các thông tin còn lại hợp lệ. 4. Click Tạo mới. | E28: Mã: CNT003 Loại: Chi nhánh Địa chỉ: 134 Nguyễn Cao, Kinh Bắc, Bắc Ninh SĐT: 0286437475 Email: cn003@shome.vn Trạng thái: ON | F28: 1. Không tạo chi nhánh. 2.Hiển thị lỗi "Tên chi nhánh là bắt buộc" ngay tại field (inline) 3. Focus vào field Tên chi nhánh 4. Không gửi request tạo mới | G28: Pass | I28: =Cover!$G$4 -> Dương Thị Ngọc Ánh
A29: TC19 | B29: Tên chi nhánh chỉ chứa khoảng trắng | D29: 1. Nhập một hoặc nhiều khoảng trắng vào 2. Nhập Mã chi nhánh. 3. Nhập các thông tin còn lại hợp lệ. 4. Click Tạo mới. | E29: Mã: CNT004 Loại: Chi nhánh Địa chỉ: 136 Nguyễn Cao, Kinh Bắc, Bắc Ninh SĐT: 0286437432 Email: cn004@shome.vn Trạng thái: ON | F29: 1. Không tạo chi nhánh. 2. Hệ thống xử lý giá trị khoảng trắng như dữ liệu rỗng. 3. Hiển thị lỗi "Tên chi nhánh là bắt buộc" ngay tại field (inline) | G29: Fail | I29: =Cover!$G$4 -> Dương Thị Ngọc Ánh | J29: 1. Tạo được chi nhánh mới. 2. Không focus vào ô tên chi nhánh, không hiển thị thông báo tên chi nhánh là bắt buộc
A30: TC20 | B30: Bỏ trống Mã chi nhánh | D30: 1. Nhập Tên chi nhánh. 2. Để trống Mã chi nhánh. 3. Nhập các thông tin còn lại hợp lệ. 4. Click Tạo mới. | E30: Tên : Chi nhánh Test 09 Mã: CNT009 Loại: Chi nhánh Địa chỉ: 9 Phố Viên, Đông Ngạc, Hà Nội SĐT: 0286437432 Email: cnt009@shome.vn Trạng thái: ON | F30: 1. Không tạo chi nhánh 2. Hiển thị lỗi "Mã chi nhánh là bắt buộc" ngay tại field (inline) 3. Focus vào field Mã chi nhánh | G30: Pass | I30: =Cover!$G$4 -> Dương Thị Ngọc Ánh
A31: TC21 | B31: Mã chi nhánh chỉ chứa khoảng trắng | D31: 1. Nhập Tên chi nhánh. 2. Nhập một hoặc nhiều khoảng trắng vào Mã chi nhánh. 4. Nhập các thông tin còn lại hợp lệ. 5. Click Tạo mới. | E31: Tên : Chi nhánh Test 10 Loại: Chi nhánh Địa chỉ: 241 Xuân Đỉnh, Hà Nội SĐT: 0357377432 Email: cnt010@shome.vn Trạng thái: ON | F31: 1. Không tạo chi nhánh. 2. Hệ thống không chấp nhận mã chỉ chứa khoảng trắng. 3. Hiển thị thông báo lỗi tương ứng. | G31: Pass | I31: =Cover!$G$4 -> Dương Thị Ngọc Ánh
A32: TC22 | B32: Mã chi nhánh chứa chữ thường | D32: 1. Nhập Tên chi nhánh. 2. Nhập Mã chi nhánh. 3. Nhập các thông tin còn lại hợp lệ. 4. Click Tạo mới. | E32: Tên : Chi nhánh Test 11 Mã: cnt011 Loại: Chi nhánh Địa chỉ: 4 Đường Nguyễn Đỗ Cung, Hòa Khánh, Đà Nẵng SĐT: 0357377456 Email: cnt011@shome.vn Trạng thái: ON | F32: 1. Hệ thống không chấp nhận mã không đúng quy tắc. 2. Hiển thị thông báo "Mã chỉ được chứa chữ hoa, số, gạch ngang và gạch dưới" 3. Không tạo bản ghi mới. | G32: Pass | I32: =Cover!$G$4 -> Dương Thị Ngọc Ánh
A33: TC23 | B33: Mã chi nhánh chứa ký tự đặc biệt | D33: 1. Nhập Tên chi nhánh. 2. Nhập Mã chi nhánh. 3. Nhập các thông tin còn lại hợp lệ. 4. Click Tạo mới. | E33: Tên: Chi nhánh Test 12 Mã: CNT@012 Loại: Chi nhánh Địa chỉ: 6 Đường Nguyễn Đỗ Cung, Hòa Khánh, Đà Nẵng SĐT: 0357377458 Email: cnt012@shome.vn Trạng thái: ON | F33: 1. Hệ thống không chấp nhận mã không đúng quy tắc. 2. Hiển thị thông báo "Mã chỉ được chứa chữ hoa, số, gạch ngang và gạch dưới" 3. Không tạo bản ghi mới. | G33: Pass | I33: =Cover!$G$4 -> Dương Thị Ngọc Ánh
A34: TC24 | B34: Mã chi nhánh chứa khoảng trắng ở giữa | D34: 1. Nhập Tên chi nhánh. 2. Nhập Mã chi nhánh. 3. Nhập các thông tin còn lại hợp lệ. 4. Click Tạo mới. | E34: Tên: Chi nhánh Test 13 Mã: CNT 013 Loại: Chi nhánh Địa chỉ: 6 Đường Nguyễn Đỗ Cung, Hòa Khánh, Đà Nẵng SĐT: 0357377458 Email: cnt012@shome.vn Trạng thái: ON | F34: 1. Hệ thống không chấp nhận mã không đúng quy tắc. 2. Hiển thị thông báo "Mã chỉ được chứa chữ hoa, số, gạch ngang và gạch dưới" 3. Không tạo bản ghi mới. | G34: Pass | I34: =Cover!$G$4 -> Dương Thị Ngọc Ánh
A35: TC25 | B35: Mã chi nhánh có dấu gạch ngang hợp lệ | D35: 1. Nhập Tên chi nhánh. 2. Nhập Mã chi nhánh. 3. Nhập các thông tin còn lại hợp lệ. 4. Click Tạo mới. | E35: Tên: Chi nhánh Test 14 Mã: CN-014 | F35: 1. Mã được chấp nhận. 2. Chi nhánh được tạo thành công. 3. Mã CN-014 được lưu đúng. | G35: Pass | I35: =Cover!$G$4 -> Dương Thị Ngọc Ánh
A36: TC26 | B36: Mã chi nhánh có dấu gạch dưới hợp lệ | D36: 1. Nhập Tên chi nhánh. 2. Nhập Mã chi nhánh. 3. Nhập các thông tin còn lại hợp lệ. 4. Click Tạo mới. | E36: Tên: Chi nhánh Test 15 Mã: CN_015 | F36: 1. Mã được chấp nhận. 2. Chi nhánh được tạo thành công. 3. Mã CN_015 được lưu đúng. | G36: Pass | I36: =Cover!$G$4 -> Dương Thị Ngọc Ánh
A37: TC27 | B37: Mã chi nhánh có dấu gạch dưới hợp lệ | C37: Hệ thống đã tồn tại chi nhánh có mã BN001 | D37: 1. Mở form Tạo chi nhánh. 2. Nhập Tên Chi nhánh. 3. Nhập Mã. 4. Nhập các thông tin còn lại hợp lệ. 5. Click Tạo mới. | E37: Tên: Chi nhánh Test 16 Mã: BN001 | F37: 1. Không tạo chi nhánh mới. 2. Hiển thị lỗi mã chi nhánh đã tồn tại. 3. Không tạo thêm bản ghi có mã BN001. | G37: Fail | I37: =Cover!$G$4 -> Dương Thị Ngọc Ánh | J37: Không focus vào ô mã chi nhánh, có thông báo"Có lỗ xảy ra khi tạo chi nhánh"
A38: TC28 | B38: Số điện thoại 10 chữ số | D38: 1. Nhập đầy đủ Tên và Mã hợp lệ. 2. Nhập SĐT 10 số. 3. Nhập các thông tin còn lại hợp lệ. 4. Click Tạo mới. | E38: Tên: Chi nhánh Test 17 Mã: CNT017 Loại: Chi nhánh Địa chỉ: 4 Đường Nguyễn Đỗ Cung, Hòa Khánh, Đà Nẵng SĐT: 0357377456 Email: cnt017@shome.vn Trạng thái: ON | F38: 1. Hệ thống chấp nhận số điện thoại. 2. Chi nhánh được tạo thành công. 3. SĐT được lưu đúng. | G38: Pass | I38: =Cover!$G$4 -> Dương Thị Ngọc Ánh
A39: TC29 | B39: Số điện thoại 11 chữ số | D39: 1. Nhập đầy đủ Tên và Mã hợp lệ. 2. Nhập SĐT. 3. Nhập các thông tin còn lại hợp lệ. 4. Click Tạo mới. | E39: Tên: Chi nhánh Test 18 Mã: CNT018 Loại: Chi nhánh Địa chỉ: 4 Đường Nguyễn Đỗ Cung, Hòa Khánh, Đà Nẵng SĐT: 03573774567 Email: cnt018@shome.vn Trạng thái: ON | F39: 1. Hệ thống chấp nhận số điện thoại. 2. Chi nhánh được tạo thành công. 3. SĐT được lưu đúng. | G39: Pass | I39: =Cover!$G$4 -> Dương Thị Ngọc Ánh
A40: TC30 | B40: Số điện thoại không hợp lệ | D40: 1. Nhập đầy đủ Tên và Mã hợp lệ. 2. Nhập SĐT. 3. Nhập các thông tin còn lại hợp lệ. 4. Click Tạo mới. | E40: Tên: Chi nhánh Test 19 Mã: CNT019 Loại: Chi nhánh Địa chỉ: 4 Đường Nguyễn Đỗ Cung, Hòa Khánh, Đà Nẵng SĐT: 0357 Email: cnt019@shome.vn Trạng thái: ON | F40: 1. Không tạo chi nhánh. 2. Hiển thị lỗi số điện thoại không hợp lệ. 3. Hệ thống yêu cầu số điện thoại từ 10–11 chữ số. | G40: Fail | I40: =Cover!$G$4 -> Dương Thị Ngọc Ánh | J40: 1. Tạo được chi nhánh mới 2. Không hiển thị lỗi nhập sđt
B41: 2. Sửa chi nhánh
...

Sheet Test QuanLyThuongHieu
A1: Item Test | B1: QuanLyThuongHieu
A2: Test requirement | B2: Kiểm thử chức năng tạo thương hiệu
A3: Tester | B3: =Cover!$G$4 -> Dương Thị Ngọc Ánh
A4: Pass | B4: Fail | C4: NT | D4: N/A | E4: Number of Test cases
A5: =COUNTIF(G:G,"Pass") -> 25 | B5: =COUNTIF(G:G,"Fail") -> 9 | C5: =COUNTIF(G:G,"Untested") -> 0 | D5: =COUNTIF(G:G,"N/A") -> 0 | E5: =SUM(A5:D5) -> 34
A6: % | B6: % | C6: % | D6: %
A7: =IFERROR(A5/$E$5,0) -> 0.73529412 | B7: =IFERROR(B5/$E$5,0) -> 0.26470588 | C7: =IFERROR(C5/$E$5,0) -> 0 | D7: =IFERROR(D5/$E$5,0) -> 0 | E7: =IFERROR(E5/$E$5,0) -> 1
A8: ID | B8: Test Case Description | C8: Pre-condition | D8: Test Case Procedure | E8: Test Data | F8: Expected Output | G8: Result | H8: Test date | I8: Tester | J8: Note
B10: 1. Thêm chi nhánh
A11: TC01 | B11: Kiểm tra tiêu đề section "Thông tin cơ bản" | C11: Đã đăng nhập với tài khoản Quản trị viên và có quyền tạo thương hiệu | D11: Vào màn hình, quan sát section | E11: … | F11: 1. Hiển thị chữ "Thông tin cơ bản" 2. Font-size, font-weight đúng design | G11: Pass | I11: =Cover!$G$4 -> Dương Thị Ngọc Ánh
A12: TC02 | B12: Kiểm tra label "Tên thương hiệu" | D12: Vào màn hình, quan sát label | E12: … | F12: 1. Label: Tên thương hiệu 2. Căn lề, font-size, font-weight, màu sắc đúng design | G12: Pass | I12: =Cover!$G$4 -> Dương Thị Ngọc Ánh
A13: TC03 | B13: Kiểm tra textbox "Tên thương hiệu" | D13: Vào màn hình, quan sát textbox | E13: … | F13: 1. Hiển thị textbox với border, padding, height đúng design 2. Hiển thị placeholder "Nhập tên thương hiệu" 3. Chiều rộng full theo layout 4. Border-radius, màu border đúng design | G13: Pass | I13: =Cover!$G$4 -> Dương Thị Ngọc Ánh
A14: TC04 | B14: Kiểm tra label "Slug" | D14: Vào màn hình, quan sát label | E14: … | F14: 1. Label: Slug 2. Font-size, font-weight đúng design | G14: Pass | I14: =Cover!$G$4 -> Dương Thị Ngọc Ánh
A15: TC05 | B15: Kiểm tra textbox "Slug" | D15: Vào màn hình, quan sát textbox | E15: … | F15: 1. Hiển thị textbox với border, padding, height đúng design 2. Hiển thị placeholder "ten-thuong-hieu" 3. Border-radius, màu border đúng design | G15: Pass | I15: =Cover!$G$4 -> Dương Thị Ngọc Ánh
A16: TC06 | B16: Kiểm tra dòng ghi chú dưới "Slug" | D16: Vào màn hình, quan sát text dưới field | E16: … | F16: 1. Hiển thị chữ "Tự động tạo nếu để trống" 2. Font-size, màu sắc đúng design | G16: Pass | I16: =Cover!$G$4 -> Dương Thị Ngọc Ánh
A17: TC07 | B17: Kiểm tra label "Logo thương hiệu" | D17: Vào màn hình, quan sát label | E17: … | F17: 1. Label: Logo thương hiệu, màu cam/nổi bật 2. Font-size, font-weight đúng design | G17: Pass | I17: =Cover!$G$4 -> Dương Thị Ngọc Ánh
A18: TC08 | B18: Kiểm tra khu vực upload "Logo thương hiệu" | D18: Vào màn hình, quan sát khu vực upload | E18: … | F18: 1. Hiển thị khung viền nét đứt (dashed border) màu cam 2. Chiều cao, chiều rộng đúng design 3. Có hướng dẫn/icon upload (kéo thả hoặc click để chọn file) hiển thị rõ ràng bên trong khung | G18: Pass | I18: =Cover!$G$4 -> Dương Thị Ngọc Ánh
A19: TC09 | B19: Kiểm tra label "Thứ tự hiển thị" | D19: Vào màn hình, quan sát label | E19: … | F19: 1. Label: Thứ tự hiển thị, màu cam/nổi bật 2. Font-size, font-weight đúng design | G19: Pass | I19: =Cover!$G$4 -> Dương Thị Ngọc Ánh
A20: TC10 | B20: Kiểm tra textbox "Thứ tự hiển thị" giá trị mặc định | D20: Vào màn hình, quan sát textbox | E20: … | F20: 1. Hiển thị giá trị mặc định "0" 2. Chỉ cho phép nhập số 3. Border, padding, border-radius đúng design | G20: Pass | I20: =Cover!$G$4 -> Dương Thị Ngọc Ánh
A21: TC11 | B21: Kiểm tra label "Trạng thái" | D21: Vào màn hình, quan sát label | E21: … | F21: 1. Label: Trạng thái, màu cam/nổi bật 2. Font-size, font-weight đúng design | G21: Pass | I21: =Cover!$G$4 -> Dương Thị Ngọc Ánh
A22: TC12 | B22: Kiểm tra dropdown "Trạng thái" giá trị mặc định | D22: Vào màn hình, quan sát dropdown | E22: … | F22: 1. Hiển thị dropdown với giá trị mặc định "Kích hoạt" 2. Có icon mũi tên xổ xuống bên phải 3. Border, padding, border-radius đúng design | G22: Pass | I22: =Cover!$G$4 -> Dương Thị Ngọc Ánh
A23: TC13 | B23: Kiểm tra click mở dropdown "Trạng thái" | D23: Click vào dropdown "Trạng thái" | E23: … | F23: 1. Hiển thị danh sách các trạng thái xổ xuống (vd: Kích hoạt, Ngừng kích hoạt) 2. Đầy đủ các option | G23: Pass | I23: =Cover!$G$4 -> Dương Thị Ngọc Ánh
... A26: TC16 | B26: Kiểm tra footer "© 2026, Copyright by S.HOME" | D26: Cuộn xuống cuối trang | E26: … | F26: 1. Hiển thị đúng text copyright 2. "S.HOME" hiển thị màu cam nổi bật, có thể là link | G26: Pass | I26: =Cover!$G$4 -> Dương Thị Ngọc Ánh
A27: TC17 | B27: Tạo thương hiệu với đầy đủ dữ liệu hợp lệ | C27: Đăng nhập thành công, vào màn hình Tạo thương hiệu mới | D27: 1. Truy cập màn hình “Tạo thương hiệu”. 2. Nhập Tên thương hiệu. 3. Nhập Slug. 4. Click khu vực upload Logo. 5. Chọn file logo.jpg. 6. Nhập Thứ tự hiển thị. 7. Chọn trạng thái. 8. Click “Tạo thương hiệu mới”. 9. Kiểm tra thông báo và danh sách thương hiệu. 10. Reload trang và kiểm tra lại thương hiệu vừa tạo. | E27: Tên thương hiệu: Test Brand 001 Slug: test-brand-001 Logo: R.jpg Thứ tự hiển thị: 1 Trạng thái: Kích hoạt | F27: 1. Tạo thương hiệu thành công. 2. Hiển thị thông báo “Tạo thương hiệu thành công”. 3. Thông tin thương hiệu được lưu đúng. 4. Logo được lưu đúng. 5. Dữ liệu vẫn còn sau khi reload. | G27: Fail | I27: =Cover!$G$4 -> Dương Thị Ngọc Ánh | J27: Không upload được logo
A28: TC18 | B28: Tạo thương hiệu chỉ nhập trường bắt buộc | D28: 1. Truy cập màn hình “Tạo thương hiệu”. 2. Nhập Tên thương hiệu. 3. Không nhập Slug. 4. Không upload Logo. 5. Giữ Thứ tự hiển thị là 0. 6. Giữ Trạng thái là Kích hoạt. 7. Click “Tạo thương hiệu mới”. 8. Kiểm tra thương hiệu vừa tạo. | E28: Tên thương hiệu: Test Brand 002 Thứ tự hiển thị: 0 Trạng thái: Kích hoạt | F28: 1. Tạo thương hiệu thành công. 2. Hệ thống tự sinh Slug. 3. Không yêu cầu upload Logo. 4. Thứ tự hiển thị là 0. 5. Trạng thái là Kích hoạt. | G28: Pass | I28: =Cover!$G$4 -> Dương Thị Ngọc Ánh
A29: TC19 | B29: Bỏ trống Tên thương hiệu | D29: 1. Truy cập màn hình “Tạo thương hiệu”. 2. Để trống Tên thương hiệu. 3. Nhập Slug. 4. Click “Tạo thương hiệu mới”. | E29: … | F29: 1. Không tạo thương hiệu. 2. Hiển thị lỗi "Vui lòng nhập tên thương hiệu" ngay tại field (inline) 3. Focus vào field Tên thương hiệu 4. Không gửi request tạo mới | G29: Pass | I29: =Cover!$G$4 -> Dương Thị Ngọc Ánh
A30: TC20 | B30: Nhập Tên thương hiệu chỉ chứa khoảng trắng | D30: 1. Truy cập màn hình “Tạo thương hiệu”. 2. Nhập một chuỗi chỉ gồm khoảng trắng vào Tên thương hiệu. 3. Nhập Slug. 4. Click “Tạo thương hiệu mới”. | E30: … | F30: 1. Không tạo thương hiệu. 2. Hệ thống coi giá trị chỉ chứa khoảng trắng là rỗng. 3. Hiển thị lỗi “Tên thương hiệu là bắt buộc” hoặc thông báo tương đương theo SRS. | G30: Fail | I30: =Cover!$G$4 -> Dương Thị Ngọc Ánh | J30: Vẫn tạo được thương hiệu
A31: TC21 | B31: Tên thương hiệu bị trùng | D31: 1. Truy cập màn hình “Tạo thương hiệu”. 2. Nhập Tên thương hiệu. 3. Nhập Slug. 4. Click “Tạo thương hiệu mới”. | E31: Tên thương hiệu: Apple Slug: apple-test-002 | F31: 1. Không tạo thương hiệu mới. 2. Hiển thị lỗi “Tên thương hiệu đã tồn tại trong hệ thống”. 3. Không tạo thêm bản ghi trùng. | G31: Fail | I31: =Cover!$G$4 -> Dương Thị Ngọc Ánh | J31: Vẫn tạo được thương hiệu
A32: TC22 | B32: Slug chứa chữ hoa | D32: 1. Mở form Tạo thương hiệu. 2. Nhập Tên thương hiệu. 3. Nhập Slug. 4. Click “Tạo thương hiệu mới”. | E32: Tên thương hiệu: Test Brand 005 Slug: Test-Brand-005 | F32: 1. Hệ thống không chấp nhận Slug sai định dạng. 2. Hiển thị lỗi “Slug chỉ chứa chữ thường, số và gạch ngang” hoặc thông báo tương đương. | G32: Fail | I32: =Cover!$G$4 -> Dương Thị Ngọc Ánh | J32: Vẫn tạo được thương hiệu
A33: TC23 | B33: Slug chứa khoảng trắng | D33: Mở form Tạo thương hiệu. Nhập Tên thương hiệu. Nhập test brand 006 vào Slug. Click “Tạo thương hiệu mới”. | E33: Tên thương hiệu: Test Brand 006 Slug: test brand 006 | F33: 1. Không tạo thương hiệu với Slug không hợp lệ. 2. Hiển thị lỗi định dạng Slug. | G33: Fail | I33: =Cover!$G$4 -> Dương Thị Ngọc Ánh | J33: Vẫn tạo được thương hiệu
A34: TC24 | B34: Slug bị trùng | C34: Đã tồn tại thương hiệu có Slug apple | D34: 1. Nhập Tên chi nhánh. 2. Nhập Mã chi nhánh. 3. Chọn Loại chi nhánh. 4. Nhập địa chỉ. 5. Nhập số điện thoại. 6. Nhập email. 7. Giữ toggle Đang hoạt động ở trạng thái ON. 8. Click Tạo mới. 9. Mở lại danh sách chi nhánh. | F34: 1. Không tạo thương hiệu. 2. Hiển thị “Slug đã tồn tại”. | G34: Fail | I34: =Cover!$G$4 -> Dương Thị Ngọc Ánh | J34: Vẫn tạo được thương hiệu
A35: TC25 | B35: Upload Logo định dạng JPG | D35: 1. Mở form Tạo thương hiệu. 2. Nhập Tên thương hiệu. 3. Nhập Slug. 4. Click khu vực upload Logo. 5. Chọn file logo.jpg. 6. Quan sát khu vực upload. | E35: Tên thương hiệu: Test Brand 009 Slug: test-brand-009 Logo: logo.jpg | F35: 1. File JPG được chấp nhận. 2. Logo hiển thị preview. 3. Có thể tiếp tục tạo thương hiệu. | G35: Fail | I35: =Cover!$G$4 -> Dương Thị Ngọc Ánh | J35: Không upload được logo
A36: TC26 | B36: Upload Logo định dạng PNG | D36: 1. Mở form Tạo thương hiệu. 2. Nhập Tên thương hiệu. 3. Nhập Slug. 4. Click khu vực upload Logo. 5. Chọn logo.png. 6. Quan sát preview. | E36: Tên thương hiệu: Test Brand 010 Slug: test-brand-010 Logo: logo.png | F36: 1. File PNG được chấp nhận. 2. Logo hiển thị preview. | G36: Fail | I36: =Cover!$G$4 -> Dương Thị Ngọc Ánh | J36: Không upload được logo
A37: TC27 | B37: Upload Logo sai định dạng | D37: 1. Mở form Tạo thương hiệu. 2. Nhập Tên thương hiệu. 3. Nhập Slug. 4. Click khu vực upload Logo. 5. Chọn file document.pdf. 6. Quan sát kết quả. | E37: Tên thương hiệu: Test Brand 011 Slug: test-brand-011 Logo: document.pdf | F37: 1. UI chặn không cho chọn 2. Không upload được file | G37: Pass | I37: =Cover!$G$4 -> Dương Thị Ngọc Ánh
A38: TC28 | B38: Thay đổi Logo trước khi tạo | D38: 1. Mở form Tạo thương hiệu. 2. Nhập Tên thương hiệu. 3. Nhập Slug. 4. Upload logo1.jpg. 5. Quan sát preview. 6. Thực hiện thao tác thay đổi Logo. 7. Chọn logo2.png. 8. Quan sát preview. 9. Click “Tạo thương hiệu mới”. | E38: Tên thương hiệu: Test Brand 012 Slug: test-brand-012 Logo ban đầu: logo1.jpg Logo thay thế: logo2.png | F38: 1. logo1.jpg được upload và hiển thị preview. 2. Khi thay đổi Logo, ảnh cũ được thay thế bằng logo2.png. 3. Preview hiển thị đúng logo2.png. 4. Khi tạo thương hiệu, hệ thống lưu Logo mới (logo2.png). | G38: Fail | I38: =Cover!$G$4 -> Dương Thị Ngọc Ánh | J38: Không upload được logo
A39: TC29 | B39: Nhập Thứ tự hiển thị bằng số nguyên dương | D39: 1. Mở form Tạo thương hiệu. 2. Nhập Tên thương hiệu. 3. Nhập Slug. 4. Nhập Thứ tự hiển thị 5. Click “Tạo thương hiệu mới”. | E39: Tên thương hiệu: Test Brand 013 Slug: test-brand-013 Thứ tự hiển thị: 5 | F39: 1. Hệ thống chấp nhận giá trị 5. 2. Tạo thương hiệu thành công. 3. Thứ tự hiển thị được lưu là 5. | G39: Pass | I39: =Cover!$G$4 -> Dương Thị Ngọc Ánh
A40: TC30 | B40: Nhập Thứ tự hiển thị là số âm | D40: 1. Mở form Tạo thương hiệu. 2. Nhập Tên thương hiệu. 3. Nhập Slug. 4. Nhập Thứ tự hiển thị. 5. Click “Tạo thương hiệu mới”. | E40: Tên thương hiệu: Test Brand 014 Slug: test-brand-014 Thứ tự hiển thị: -1 | F40: 1. Không cho phép nhập giá trị âm vào ô Thứ tự hiển thị. 2. Giá trị trong ô luôn ≥ 0. | G40: Pass | I40: =Cover!$G$4 -> Dương Thị Ngọc Ánh
A41: TC31 | B41: Nhập ký tự không phải số vào Thứ tự hiển thị | D41: 1. Mở form Tạo thương hiệu. 2. Nhập Tên thương hiệu. 3. Nhập Slug. 4. Nhập Thứ tự hiển thị. 5. Click “Tạo thương hiệu mới”. | E41: Tên thương hiệu: Test Brand 015 Slug: test-brand-015 Thứ tự hiển thị: abc | F41: 1. Hệ thống không chấp nhận giá trị không phải số. 2. Không tạo thương hiệu. 3. Hiển thị lỗi hoặc chặn nhập theo thiết kế. | G41: Pass | I41: =Cover!$G$4 -> Dương Thị Ngọc Ánh
A42: TC32 | B42: Tạo thương hiệu với trạng thái Kích hoạt | D42: 1. Mở form Tạo thương hiệu. 2. Nhập Tên thương hiệu. 3. Nhập Slug. 4. Nhập Thứ tự hiển thị. 5. Chọn Trạng thái. 6. Click “Tạo thương hiệu mới”. 7. Kiểm tra danh sách thương hiệu. | E42: Tên thương hiệu: Test Brand 016 Slug: test-brand-016 Thứ tự hiển thị: 1 Trạng thái: Kích hoạt | F42: 1. Tạo thành công. 2. Thương hiệu có trạng thái Kích hoạt. | G42: Pass | I42: =Cover!$G$4 -> Dương Thị Ngọc Ánh
A43: TC33 | B43: Double click nút Tạo thương hiệu mới | D43: 1. Mở form Tạo thương hiệu. 2. Nhập đầy đủ dữ liệu hợp lệ. 3. Double click nhanh vào nút “Tạo thương hiệu mới”. 4. Chờ hệ thống xử lý. 5. Kiểm tra danh sách thương hiệu. | E43: Tên thương hiệu: Test Brand 018 Slug: test-brand-018 Thứ tự hiển thị: 1 Trạng thái: Kích hoạt | F43: 1. Chỉ tạo 01 thương hiệu. 2. Không tạo bản ghi trùng. 3. Nút có trạng thái loading/disable trong lúc xử lý nếu được thiết kế như SRS yêu cầu. | G43: Pass | I43: =Cover!$G$4 -> Dương Thị Ngọc Ánh
...

Sheet Test QuanLyKho
A1: Item Test | B1: QuanLyKho
A2: Test requirement | B2: Kiểm thử chức năng tạo kho
A3: Tester | B3: =Cover!$G$4 -> Dương Thị Ngọc Ánh
A4: Pass | B4: Fail | C4: NT | D4: N/A | E4: Number of Test cases
A5: =COUNTIF(G:G,"Pass") -> 44 | B5: =COUNTIF(G:G,"Fail") -> 6 | C5: =COUNTIF(G:G,"Untested") -> 1 | D5: =COUNTIF(G:G,"N/A") -> 0 | E5: =SUM(A5:D5) -> 51
A6: % | B6: % | C6: % | D6: %
A7: =IFERROR(A5/$E$5,0) -> 0.8627451 | B7: =IFERROR(B5/$E$5,0) -> 0.11764706 | C7: =IFERROR(C5/$E$5,0) -> 0.019607843 | D7: =IFERROR(D5/$E$5,0) -> 0 | E7: =IFERROR(E5/$E$5,0) -> 1
A8: ID | B8: Test Case Description | C8: Pre-condition | D8: Test Case Procedure | E8: Test Data | F8: Expected Output | G8: Result | H8: Test date | I8: Tester | J8: Note
A10: TC01 | B10: Kiểm tra button "Lưu nháp" | D10: Vào màn hình, quan sát button | E10: … | F10: 1. Hiển thị chữ "Lưu nháp" 2. Màu nền vàng nhạt, chữ vàng đậm, border-radius đúng design 3. Vị trí góc phải trên cùng | G10: Pass | I10: =Cover!$G$4 -> Dương Thị Ngọc Ánh
A11: TC02 | B11: Kiểm tra button "Tạo" | D11: Vào màn hình, quan sát button | E11: … | F11: 1. Hiển thị chữ "Tạo" 2. Màu nền cam, chữ đen/đậm, border-radius đúng design 3. Vị trí góc phải trên cùng, cạnh button "Lưu nháp" | G11: Pass | I11: =Cover!$G$4 -> Dương Thị Ngọc Ánh
A12: TC03 | B12: Kiểm tra tiêu đề section "Thông tin kho" | D12: Vào màn hình, quan sát section | E12: … | F12: 1. Hiển thị chữ "Thông tin kho" 2. Font-size, font-weight đúng design | G12: Pass | I12: =Cover!$G$4 -> Dương Thị Ngọc Ánh
A13: TC04 | B13: Kiểm tra label "Mã kho" | D13: Vào màn hình, quan sát label | E13: … | F13: 1. Label: Mã kho, màu cam/nổi bật 2. Font-size, font-weight đúng design | G13: Pass | I13: =Cover!$G$4 -> Dương Thị Ngọc Ánh
A14: TC05 | B14: Kiểm tra textbox "Mã kho" | D14: Vào màn hình, quan sát textbox | E14: … | F14: 1. Hiển thị textbox với border, padding, height đúng design 2. Hiển thị placeholder "Nhập mã kho" 3. Border-radius, màu border đúng design | G14: Pass | I14: =Cover!$G$4 -> Dương Thị Ngọc Ánh
A15: TC06 | B15: Kiểm tra label "Tên kho" | D15: Vào màn hình, quan sát label | E15: … | F15: 1. Label: Tên kho, màu cam/nổi bật 2. Font-size, font-weight đúng design | G15: Pass | I15: =Cover!$G$4 -> Dương Thị Ngọc Ánh
A16: TC07 | B16: Kiểm tra textbox "Tên kho" | D16: Vào màn hình, quan sát textbox | E16: … | F16: 1. Hiển thị textbox với border, padding, height đúng design 2. Hiển thị placeholder "Nhập tên kho" 3. Border-radius, màu border đúng design | G16: Pass | I16: =Cover!$G$4 -> Dương Thị Ngọc Ánh
A17: TC08 | B17: Kiểm tra label "Chi nhánh" | D17: Vào màn hình, quan sát label | E17: … | F17: 1. Label: Chi nhánh 2. Font-size, font-weight đúng design | G17: Pass | I17: =Cover!$G$4 -> Dương Thị Ngọc Ánh
A18: TC09 | B18: Kiểm tra dropdown "Chi nhánh" | D18: Vào màn hình, quan sát dropdown | E18: … | F18: 1. Hiển thị dropdown với border, padding, height đúng design 2. Không có giá trị mặc định (trống) 3. Có icon mũi tên xổ xuống bên phải | G18: Pass | I18: =Cover!$G$4 -> Dương Thị Ngọc Ánh
A19: TC10 | B19: Kiểm tra click mở dropdown "Chi nhánh" | D19: Click vào dropdown "Chi nhánh" | E19: … | F19: 1. Hiển thị danh sách các chi nhánh đang tồn tại xổ xuống đầy đủ | G19: Pass | I19: =Cover!$G$4 -> Dương Thị Ngọc Ánh
A20: TC11 | B20: Kiểm tra chọn giá trị trong dropdown "Chi nhánh" | D20: 1. Click dropdown 2. Chọn 1 chi nhánh | E20: … | F20: 1. Giá trị được chọn hiển thị đúng trong dropdown 2. Dropdown đóng lại | G20: Pass | I20: =Cover!$G$4 -> Dương Thị Ngọc Ánh
A21: TC12 | B21: Kiểm tra label "Trạng thái" | D21: Vào màn hình, quan sát label | E21: … | F21: 1. Label: Trạng thái 2. Font-size, font-weight đúng design | G21: Pass | I21: =Cover!$G$4 -> Dương Thị Ngọc Ánh
... A40: TC31 | B40: Tạo kho với đầy đủ thông tin theo địa chỉ Cũ (3 cấp) | D40: 1. Mở màn hình Tạo kho. 2. Nhập Mã kho. 3. Nhập Tên kho. 4. Chọn Chi nhánh. 5. Giữ Trạng thái. 6. Chọn Đơn vị hành chính. 7. Chọn Tỉnh/Thành phố. 8. Chọn Quận/Huyện. 9. Chọn Phường/Xã. 10. Nhập Địa chỉ chi tiết. 11. Nhập Ghi chú. 12. Click Tạo. 13. Kiểm tra thông báo và danh sách kho. 14. Reload trang và kiểm tra lại kho. | E40: Mã kho: KHO001 Tên kho: Kho Quận 1 Chi nhánh: Chi nhánh Quận 1 Trạng thái: Hoạt động Đơn vị hành chính: Cũ (3 cấp) Tỉnh/Thành phố: TP. Hồ Chí Minh Quận/Huyện: Quận 1 Phường/Xã: Phường Bến Nghé Địa chỉ chi tiết: 123 Nguyễn Huệ Ghi chú: Kho trung tâm Quận 1 | F40: 1. Tạo kho thành công. 2. Hiển thị thông báo “Tạo kho thành công”. 3. Dữ liệu được lưu đúng. 4. Kho hiển thị trong danh sách. 5. Dữ liệu vẫn còn sau khi reload. | G40: Pass | I40: =Cover!$G$4 -> Dương Thị Ngọc Ánh
A41: TC32 | B41: Tạo kho với địa chỉ Mới (2 cấp) | C41: Đã đăng nhập QTV; đã có sẵn 1 bản ghi kho trạng thái Nháp | D41: 1. Mở màn hình Tạo kho. 2. Nhập Mã kho. 3. Nhập Tên kho. 4. Chọn chi nhánh. 5. Chọn Trạng thái. 6. Chọn Đơn vị hành chính. 7. Chọn Tỉnh/Thành phố. 8. Kiểm tra giao diện sau khi chọn Tỉnh/Thành phố. 9. Chọn Phường/Xã. 10. Nhập địa chỉ chi tiết. 11. Nhập ghi chú. 12. Click Tạo. 13. Kiểm tra kết quả. | E41: Mã kho: KHO002 Tên kho: Kho Ba Đình Chi nhánh: Chi nhánh Hà Nội Trạng thái: Hoạt động Đơn vị hành chính: Mới (2 cấp) Tỉnh/Thành phố: Hà Nội Phường/Xã: Ba Đình Địa chỉ chi tiết: 123 Đội Cấn Ghi chú: Kho Hà Nội | F41: 1. Khi chọn Mới (2 cấp), form chỉ hiển thị Tỉnh/Thành phố và Phường/Xã. 2. Tạo kho thành công. 3. Dữ liệu được lưu đúng. | G41: Pass | I41: =Cover!$G$4 -> Dương Thị Ngọc Ánh
A42: TC34 | B42: Bỏ trống Mã kho | D42: 1. Mở màn hình Tạo kho. 2. Để trống Mã kho. 3. Nhập Tên kho. 4. Click Tạo. | E42: Tên kho: Kho Test 003 Chi nhánh: Chi nhánh Hà Nội Trạng thái: Hoạt động Đơn vị hành chính: Mới (2 cấp) Tỉnh/Thành phố: Hà Nội Phường/Xã: Long Biên Địa chỉ chi tiết: 48 Ngô Gia Tự Ghi chú: Kho Hà Nội | F42: 1. Không tạo kho. 2. Hiển thị lỗi “Mã kho là bắt buộc”. 3. Không tạo bản ghi kho. | G42: Pass | I42: =Cover!$G$4 -> Dương Thị Ngọc Ánh
A43: TC35 | B43: Mã kho chỉ chứa khoảng trắng | D43: 1. Mở màn hình Tạo kho. 2. Nhập khoảng trắng vào Mã kho. 3. Nhập Tên kho. 4. Click Tạo. | E43: Tên kho: Kho Test 004 Chi nhánh: Chi nhánh Hà Nội Trạng thái: Hoạt động Đơn vị hành chính: Mới (2 cấp) Tỉnh/Thành phố: Hà Nội Phường/Xã: Long Biên Địa chỉ chi tiết: 48 Ngô Gia Tự Ghi chú: Kho Hà Nội | F43: 1. Hệ thống coi Mã kho sau khi trim là rỗng. 2. Không tạo kho. 3. Hiển thị lỗi “Mã kho là bắt buộc”. | G43: Fail | I43: =Cover!$G$4 -> Dương Thị Ngọc Ánh | J43: Tạo được kho
A44: TC36 | B44: Mã kho hợp lệ chỉ chứa chữ và số | D44: 1. Mở màn hình Tạo kho. 2. Nhập Mã kho. 3. Nhập Tên kho. 4. Chọn các thông tin địa chỉ cần thiết. 5. Click Tạo. | E44: Mã kho: KHO005 Tên kho: Kho Test 005 Chi nhánh: Chi nhánh Bắc Ninh mới Trạng thái: Hoạt động Đơn vị hành chính: Mới (2 cấp) Tỉnh/Thành phố: Bắc Ninh Phường/Xã: Bắc Giang Địa chỉ chi tiết: 48 Hoàng Hoa Thám Ghi chú: Kho Bắc Ninh | F44: 1. Mã kho được chấp nhận. 2. Kho được tạo thành công nếu các dữ liệu bắt buộc khác hợp lệ. | G44: Pass | I44: =Cover!$G$4 -> Dương Thị Ngọc Ánh
A45: TC37 | B45: Mã kho có dấu gạch ngang | D45: 1. Mở màn hình Tạo kho. 2. Nhập Mã kho. 3. Nhập Tên kho. 4. Nhập/chọn các dữ liệu bắt buộc. 5. Click Tạo. | E45: Mã kho: KHO-006 Tên kho: Kho Test 006 Chi nhánh: Chi nhánh Quân 1 Trạng thái: Hoạt động Đơn vị hành chính: Mới (2 cấp) Tỉnh/Thành phố: Hồ Chí Minh Phường/Xã: Thủ Đức Địa chỉ chi tiết: 20 Đường số 1 Ghi chú: Kho Thủ Đức | F45: 1. Mã kho được chấp nhận. 2. Không hiển thị lỗi định dạng. | G45: Pass | I45: =Cover!$G$4 -> Dương Thị Ngọc Ánh
A46: TC38 | B46: Mã kho có dấu gạch dưới | D46: 1. Mở màn hình Tạo kho. 2. Nhập Mã kho. 3. Nhập Tên kho. 4. Nhập/chọn các dữ liệu bắt buộc. 5. Click Tạo. | E46: Mã kho: KHO_007 Tên kho: Kho Test 007 Chi nhánh: Chi nhánh Test 19 Trạng thái: Hoạt động Đơn vị hành chính: Mới (2 cấp) Tỉnh/Thành phố: Hồ Chí Minh Phường/Xã: Thủ Đức Địa chỉ chi tiết: 20 Đường số 1 Ghi chú: Kho Thủ Đức | F46: 1. Mã kho được chấp nhận. 2. Không hiển thị lỗi định dạng. | G46: Pass | I46: =Cover!$G$4 -> Dương Thị Ngọc Ánh
A47: TC39 | B47: Mã kho chứa ký tự không hợp lệ | D47: 1. Mở màn hình Tạo kho. 2. Nhập Mã kho. 3. Nhập Tên kho. 4. Nhập/chọn các dữ liệu bắt buộc. 5. Click Tạo. | E47: Mã kho: KHO008! Tên kho: Kho Test 008 Chi nhánh: Chi nhánh Test 17 Trạng thái: Hoạt động Đơn vị hành chính: Mới (2 cấp) Tỉnh/Thành phố: Điện Biên Phường/Xã: Mường Nhé Địa chỉ chi tiết: 1 National Route Ghi chú: Kho Thủ Đức | F47: 1. Không tạo kho. 2. Hiển thị lỗi “Mã kho chỉ chứa chữ cái, số, gạch ngang và gạch dưới” hoặc thông báo tương đương. | G47: Fail | I47: =Cover!$G$4 -> Dương Thị Ngọc Ánh | J47: Tạo được kho
A48: TC40 | B48: Mã kho bị trùng | C48: Đã tồn tại kho có Mã kho KHO005. | D48: 1. Mở màn hình Tạo kho. 2. Nhập KHO001. 3. Nhập Kho Test Trùng. 4. Nhập/chọn các dữ liệu bắt buộc. 5. Click Tạo. | E48: Mã kho: KHO005 Tên kho: Kho Test Trùng | F48: 1. Không tạo kho. 2. Hiển thị lỗi “Mã kho đã tồn tại trong hệ thống”. 3. Không tạo bản ghi trùng. | G48: Fail | I48: =Cover!$G$4 -> Dương Thị Ngọc Ánh | J48: Không hiển thị thông báo mã kho đã tồn tại
A49: TC41 | B49: Mã kho trùng nhưng khác chữ hoa/chữ thường | D49: 1. Đảm bảo đã có kho với mã KHO005. 2. Mở màn hình Tạo kho. 3. Nhập mã kho. 4. Nhập Tên kho. 5. Nhập/chọn các dữ liệu bắt buộc. 6. Click Tạo. | E49: Mã kho đã tồn tại: KHO0015 Mã kho nhập: KhO005 Tên kho: Kho Test Trùng | F49: 1. Hệ thống coi KhO005 và KHO005 là cùng một mã. 2. Không tạo kho. 3. Hiển thị lỗi mã kho đã tồn tại. | G49: Fail | I49: =Cover!$G$4 -> Dương Thị Ngọc Ánh | J49: vẫn tạo kho
A50: TC43 | B50: Bỏ trống Tên kho | D50: 1. Mở màn hình Tạo kho. 2. Nhập Mã kho. 3. Để trống Tên kho. 4. Nhập/chọn các dữ liệu bắt buộc khác. 5. Click Tạo. | E50: Mã kho: KHO013 | F50: 1. Không tạo kho. 2. Hiển thị lỗi “Tên kho là bắt buộc”. | G50: Pass | I50: =Cover!$G$4 -> Dương Thị Ngọc Ánh
A51: TC44 | B51: Tên kho chỉ chứa khoảng trắng | D51: 1. Mở màn hình Tạo kho. 2. Nhập Mã kho. 3. Nhập khoảng trắng vào Tên kho. 4. Nhập/chọn các dữ liệu bắt buộc khác. 5. Click Tạo. | E51: Mã kho: KHO014 | F51: 1. Hệ thống coi Tên kho sau khi trim là rỗng. 2. Không tạo kho. 3. Hiển thị lỗi “Tên kho là bắt buộc”. | G51: Fail | I51: =Cover!$G$4 -> Dương Thị Ngọc Ánh | J51: vẫn tạo kho
A52: TC46 | B52: Kiểm tra Quận/Huyện khi chưa chọn Tỉnh/Thành phố | D52: 1. Mở màn hình Tạo kho. 2. Không chọn Tỉnh/Thành phố. 3. Click/quan sát dropdown Quận/Huyện. | F52: 1. Quận/Huyện ở trạng thái disable. 2. Không có dữ liệu để lựa chọn. 3. Hệ thống yêu cầu chọn Tỉnh/Thành phố trước. | G52: Pass | I52: =Cover!$G$4 -> Dương Thị Ngọc Ánh
A53: TC47 | B53: Kiểm tra Quận/Huyện sau khi chọn Tỉnh/Thành phố | D53: 1. Mở màn hình Tạo kho. 2. Chọn Cũ (3 cấp). 3. Chọn TP. Hồ Chí Minh. 4. Quan sát dropdown Quận/Huyện. | F53: 1. Quận/Huyện được chuyển sang trạng thái active. 2. Danh sách Quận/Huyện được load tương ứng với Tỉnh/Thành phố đã chọn. | G53: Pass | I53: =Cover!$G$4 -> Dương Thị Ngọc Ánh
A54: TC48 | B54: Kiểm tra Phường/Xã khi chưa chọn Quận/Huyện | D54: 1. Chọn Tỉnh/Thành phố. 2. Không chọn Quận/Huyện. 3. Quan sát dropdown Phường/Xã. | F54: 1. Phường/Xã ở trạng thái disable. 2. Không cho lựa chọn khi chưa có Quận/Huyện. | G54: Pass | I54: =Cover!$G$4 -> Dương Thị Ngọc Ánh
A55: TC49 | B55: Kiểm tra Phường/Xã sau khi chọn Quận/Huyện | D55: 1. Chọn Tỉnh/Thành phố. 2. Chọn Quận/Huyện. 3. Quan sát dropdown Phường/Xã. | F55: 1. Phường/Xã chuyển sang active. 2. Danh sách Phường/Xã được load tương ứng với Quận/Huyện đã chọn. | G55: Pass | I55: =Cover!$G$4 -> Dương Thị Ngọc Ánh
A56: TC51 | B56: Lưu nháp khi dữ liệu chưa đầy đủ | D56: 1. Mở màn hình Tạo kho. 2. Nhập "Kho nháp 001" vào Tên kho. 3. Không nhập Mã kho. 4. Không nhập các thông tin còn lại. 5. Click “Lưu nháp”. 6. Kiểm tra thông báo. 7. Kiểm tra danh sách kho. | F56: 1. Cho phép lưu dù dữ liệu chưa đầy đủ. 2. Hiển thị “Lưu nháp thành công”. 3. Kho được lưu với trạng thái Nháp. | G56: Fail | I56: =Cover!$G$4 -> Dương Thị Ngọc Ánh | J56: Không lưu nháp được
A57: TC52 | B57: Mở lại kho nháp và tạo chính thức | C57: Đã có một kho đang ở trạng thái Nháp. | D57: Truy cập danh sách kho. 1. Mở kho đang ở trạng thái Nháp. 2. Nhập/bổ sung Mã kho KHO016. 3. Kiểm tra và bổ sung Tên kho nếu cần. 4. Bổ sung các thông tin bắt buộc còn thiếu. 5. Click Tạo. Kiểm tra kết quả. | F57: 1. Phường/Xã chuyển sang active. 2. Danh sách Phường/Xã được load tương ứng với Quận/Huyện đã chọn. | G57: Untested | I57: =Cover!$G$4 -> Dương Thị Ngọc Ánh
A58: TC55 | B58: Tạo kho với trạng thái khác mặc định | D58: 1. Mở form Tạo kho. 2. Nhập Mã kho. 3. Nhập Tên kho. 4. Chọn một trạng thái khác giá trị mặc định nếu danh sách trạng thái có hỗ trợ. 5. Bổ sung dữ liệu bắt buộc. 6. Click Tạo. 7. Kiểm tra danh sách. | E58: Mã kho: KHO018 Tên kho: Kho Test Trạng Thái Trạng thái: [giá trị khác Hoạt động nếu dropdown hỗ trợ] | F58: Kho được tạo thành công nếu trạng thái được chọn là hợp lệ. Trạng thái được lưu đúng theo lựa chọn. | G58: Pass | I58: =Cover!$G$4 -> Dương Thị Ngọc Ánh
A59: TC55 | B59: Double click nút Tạo | D59: 1. Mở form Tạo kho. 2. Nhập đầy đủ dữ liệu hợp lệ. 3. Double click nhanh liên tiếp vào nút Tạo. 4. Chờ hệ thống xử lý. 5. Kiểm tra danh sách kho. | E59: Mã kho: KHO019 Tên kho: Kho Test Double Click Chi nhánh: Chi nhánh Quận 1 Trạng thái: Hoạt động Tỉnh/Thành phố: TP. Hồ Chí Minh Quận/Huyện: Quận 1 Phường/Xã: Phường Bến Nghé | F59: 1. Chỉ tạo 01 kho. 2. Không tạo bản ghi trùng. 3. Nút Tạo có trạng thái loading/disable trong lúc xử lý nếu hệ thống triển khai cơ chế này. | G59: Pass | I59: =Cover!$G$4 -> Dương Thị Ngọc Ánh
...
